Workbook
Name \c: #REF!
Name \D: #REF!
Name ___TGL1: #REF!
Name ___TGL2: #REF!
Name _16001: '[2]DAF.INVEN U.O'!#REF!
Name _16002: '[2]DAF.INVEN U.O'!#REF!
Name _16003: '[2]DAF.INVEN U.O'!#REF!
Name _16004: '[2]DAF.INVEN U.O'!#REF!
Name _5: #REF!
Name _6: #REF!
Name _c: #REF!
Name _TGL1: #REF!
Name _TGL2: #REF!
Name a: #REF!
Name aa: #REF!
Name ADA: #REF!
Name Agustus: #REF!
Name aju: #REF!
Name aktiva: '[8]Daftar Aktiva'!$A$1:$F$65536
Name aktiva: '[9]Daftar Aktiva'!$A:$F
Name ALAMAT: #REF!
Name ALAMAT: #REF!
Name an: '[10]WBS (2)salah'!$2:$4
Name ANA\: #REF!
Name ANA\: #REF!
Name Angsuran: '[11]Perhitungan Pegawai Tetap'!#REF!
Name anugrah: #REF!
Name April: #REF!
Name apwSetWP: [12]MAIN!$BK$38
Name asdf: #REF!
Name b: #REF!
Name batasbps: [12]MAIN!$C$26
Name cek: #REF!
Name data: #REF!
Name datacabang: [12]MAIN!$C$25
Name dbase: #REF!
Name dbase: '[13]Lembar Penolong'!$A:$CD
Name dbase1: '[14]1721-A1_2014'!$DO$80:$ET$579
Name dbase1: '[15]1721-A1_2014'!#REF!
Name dbase2: #REF!
Name dbase2: '[16]Lembar Penolong'!$CA$1:$CJ$65536
Name dbasic: '[13]Lembar Penolong'!$C:$CB
Name dec: #REF!
Name December: #REF!
Name detil: #REF!
Name detil1cols: [12]Barang!$F$2
Name detil1rows: [12]Barang!$F$1
Name dlbps: [12]MAIN!$BK$9
Name dlppna1: [12]MAIN!$BK$18
Name dlppna2: [12]MAIN!$BK$19
Name dlppnb1: [12]MAIN!$BK$20
Name dlppnb2: [12]MAIN!$BK$21
Name dlppnb3: [12]MAIN!$BK$22
Name dltunggakan: [12]MAIN!$BK$17
Name ert: '[17]WS Gmpng'!$A$9:$AD$190
Name Excel_BuiltIn_Database: #REF!
Name Excel_BuiltIn_Print_Area: NA()
Name Excel_BuiltIn_Print_Area_1: #REF!
Name Excel_BuiltIn_Print_Area_2_1: #REF!
Name Excel_BuiltIn_Print_Titles: #REF!

Sheet SOAL KASUS
B2: KASUS PPh ORANG PRIBADI 2025
B4: Tuan Fajar seorang manajer produksi di PT Sempurna, Fajar juga pengusaha toko elektronik “Welcome” yang omsetnya masih dibawah 4,8M. Selain itu, . Fajar memiliki istri bernama Sarah sebagai seorang ibu rumah tangga.
B6: Berikut adalah informasi yang diperoleh terkait Fajar:
B8: 1. Data diri wajib pajak:
B9: Nama | D9: : Fajar
B10: NPWP | D10: : 96.999.555.1-542.000 // 3402011234560001
B11: NIK | D11: : 3402011234560001
B12: Alamat | D12: : Jl. Melati, Kelurahan Sariharjo, Kecamatan Ngaglik, Kabupaten Sleman, Daerah Istimewa Yogyakarta
B13: Telpon/faks | D13: : (0274) 555666
B14: Email | D14: : welcome.fajar@gmail.com
B15: ID TKU Tempat Usaha | D15: : 3402011234560001000000
B18: 2. Peredaran usaha tahun 2025 sebagai berikut :
B19: Bulan | C19: Penghasilan Toko Elektronik
B20: Januari | C20: 190000000
B21: Februari | C21: 200000000
B22: Maret | C22: 175000000
B23: April | C23: 300000000
B24: Mei | C24: 250000000
B25: Juni | C25: 235000000
B26: Juli | C26: 260000000
B27: Agustus | C27: 180000000
B28: September | C28: 175000000
B29: Oktober | C29: 233000000
B30: November | C30: 215000000
B31: Desember | C31: 301000000
B32: Total | C32: =SUM(C20:C31) -> 2714000000
B34: 3. Informasi tambahan :
B36: Penghasilan dari Pekerjaan
B37: - Cek Bukti Potong A1
B39: Penghasilan Yang Dikenakan Pajak Penghasilan Bersifat Final
B40: Kode | C40: Jenis Penghasilan | D40: Nilai | E40: PPh Terutang | F40: Keterangan
B41: 28-402-01 | C41: Pengalihan Hak atas Tanah dan/atau Bangunan | D41: 150000000 | E41: =D41*2.5% -> 3750000 | F41: Bulan April 2025 Fajar menjual tanahnya yang diperoleh dengan harga Rp150.000.000 di Jl. Tempel km 2,5 Sleman seluas 200 m2 seharga Rp 250.000.000,- Kepada PT Tanjung. PPh final Pasal 4 Ayat 2 sudah disetor.
B43: Penghasilan Yang Tidak Termasuk Objek Pajak
B44: Kode | C44: Jenis Penghasilan | D44: Sumber Penghasilan | F44: Penghasilan | G44: Keterangan
B45: 303 | C45: Dividen atau bagian laba | D45: CV Sehat Sentosa (NPWP : 41234567891123456) | F45: 50000000 | G45: Pada akhir tahun 2025 Fajar menerima prive dari CV Sehat Sentosa
B47: Penghasilan Neto Dalam Negeri Lainnya
B48: Kode | C48: Jenis Penghasilan | D48: Sumber Penghasilan | F48: Penghasilan | G48: Keterangan
B49: 302 | C49: Sewa harta selain tanah dan/atau bangunan | D49: Bapak Dudung (NIK : 6789876543214567) | F49: 12500000 | G49: Pada bulan April 2025 Fajar menerima penghasilan sewa mobil dari Bapak Dudung
B51: 4. Informasi Data Harta dan Hutang
B52: Data Harta :
...

Sheet BP A1
F3: KEMENTERIAN KEUANGAN | O3: BUKTI PEMOTONGAN PAJAK PENGHASILAN PASAL 21 | Z3: BP A1 | AF3: a) Bagian Umum Formulir BPA1
F4: REPUBLIK INDONESIA | O4: BAGI PEGAWAI TETAP ATAU PENSIUN YANG MENERIMA | AF4: (1) Nomor Bukti Pemotongan | AJ4: : dihasilkan melalui modul eBupot.
F5: DIREKTORAT JENDERAL PAJAK | O5: UANG TERKAIT PENSIUN SECARA BERKALA | AF5: (2) Periode Penghasilan | AJ5: : Diisi dengan masa perolehan penghasilan
AJ6: dalam tahun kalender yang bersangkutan.
AF7: : Diisi dengan nomor Formulir BPA1 yang | AJ7: Misalnya: Tuan A bekerja sejak Januari tahun
D8: NOMOR BUKTI PEMOTONGAN | K8: PERIODE PENGHASILAN | S8: SIFAT PEMOTONGAN | Y8: STATUS BUKTI PEMOTONGAN | AJ8: 2025 dan masih bekerja sampai dengan
E9: 2504311G5 | K9: Januari 2025 s.d Desember 2025 | S9: Tidak Final | Y9: Normal | AJ9: Desember tahun 2025, maka masa perolehan
C11: A. IDENTITAS PENERIMA PENGHASILAN | AJ11: penghasilannya diisi dengan 01-2025 - 12-2025.
C12: A.1 | D12: NIK/NPWP | F12: : 3402011234560001 | AF12: (3) Sifat Pemotongan | AJ12: : Diisi dengan sifat pemotongan PPh Pasal 21,
C13: A.2 | D13: Nama | F13: : Fajar | AJ13: misalnya “Tidak Final”.
C14: A.3 | D14: Alamat | F14: : Jl. Melati, Kelurahan Sariharjo, Kecamatan Ngaglik, | AF14: (4) Status Bukti Pemotongan | AJ14: : Diisi dengan status Formulir BPA1:
F15: Kabupaten Sleman, Daerah Istimewa Yogyakarta | AK15: (a) “Normal” untuk Formulir BPA1 yang
C16: A.4 | D16: Jenis Kelamin | F16: : Laki-laki | AK16: pertama kali dibuat atau belum pernah
C17: A.5 | D17: Status PTKP | F17: : K/2 | O17: A.8 | P17: Nomor Paspor | T17: : …........................................... | AK17: dibetulkan atau dibatalkan;
C18: A.6 | D18: Posisi | F18: : Manajer Produksi | O18: A.9 | P18: Kode Negara | T18: : …........................................... | AK18: (b) “Pembetulan” untuk Formulir BPA1 yang
C19: A.7 | D19: Pegawai Asing | F19: : Tidak | O19: A.10 | P19: Bekerja di Lebih dari Satu Pemberi | T19: : …........................................... | AK19: membetulkan Formulir BPA1 yang
P20: Kerja | AK20: diterbitkan sebelumnya; atau
AK21: (c) “Pembatalan” untuk Formulir BPA1 yang
C22: B. RINCIAN PENGHASILAN DAN PENGHITUNGAN PPh PASAL 21 | AK22: membatalkan Formulir BPA1 yang
C23: B.1.1 | E23: Kode Objek Pajak | H23: : 21-100-01 | M23: B.1.2 | N23: Objek Pajak | S23: : Pegawai Tetap | AK23: diterbitkan sebelumnya.
C24: B.2 | E24: Jenis Pemotongan | H24: : Setahun Penuh | AF24: b) Bagian A. Identitas Penerima Penghasilan
C25: NO | E25: URAIAN | X25: JUMLAH (Rp) | AF25: (1) Huruf A.1 | AJ25: : Diisi dengan Nomor Induk Kependudukan
C26: B.3 | E26: B.4 | X26: B.5 | AJ26: (NIK)/Nomor Pokok Wajib Pajak (NPWP)
C27: I | E27: PENGHASILAN BRUTO | AJ27: penerima penghasilan.
C28: 1. | E28: Gaji/Pensiun atau THT/JHT | X28: =20000000*12 -> 240000000 | AF28: (2) Huruf A.2 | AJ28: : Diisi dengan nama penerima penghasilan.
C29: 2. | E29: Tunjangan PPh | X29: 0 | AF29: (3) Huruf A.3 | AJ29: : Diisi dengan alamat penerima penghasilan.
C30: 3. | E30: Tunjangan Lainnya, Uang Lembur dan Sebagainya | X30: =700000*12 -> 8400000 | AF30: (4) Huruf A.4 | AJ30: : Diisi dengan jenis kelamin penerima penghasilan.
C31: 4. | E31: Honorarium dan Imbalan Lain Sejenisnya | X31: 0 | AF31: (5) Huruf A.5 | AJ31: : Diisi dengan status Penghasilan Tidak Kena
C32: 5. | E32: Premi Asuransi yang Dibayarkan Pemberi Kerja | X32: =125000*12 -> 1500000 | AJ32: Pajak (PTKP) penerima penghasilan:
C33: 6. | E33: Penerimaan Dalam bentuk Natura dan Kenikmatan Lainnya yang Dikenakan Pemotongan PPh Pasal 21 | X33: 0 | AK33: K: Kawin,
C34: 7. | E34: Tantiem, Bonus, Gratifikasi, Jasa Produksi dan THR | X34: =20000000*2 -> 40000000 | AK34: TK: Tidak Kawin,
C35: 8. | E35: Jumlah Penghasilan Bruto (1 s.d 7) | X35: =SUM(X28:AB34) -> 289900000 | AK35: HB: Suami-Istri telah Hidup Berpisah
C36: II | E36: PENGURANG PENGHASILAN BRUTO | AK36: berdasarkan putusan hakim.
C37: 9. | E37: Biaya Jabatan/Biaya Pensiun | X37: 6000000 | AK37: Jumlah tanggungan pada status yang sesuai,
C38: 10. | E38: Iuran terkait Pensiun atau Hari Tua | X38: =50000*12 -> 600000 | AK38: yaitu jumlah anggota keluarga sedarah dan
C39: 11. | E39: Zakat atau Sumbangan Keagamaan yang Bersifat Wajib yang Dibayarkan melalui Pemberi Kerja | X39: 0 | AK39: keluarga semenda dalam garis keturunan
C40: 12. | E40: Jumlah Pengurang (9 s.d 11) | X40: =SUM(X37:AB39) -> 6600000 | AK40: lurus serta anak angkat yang menjadi
C41: III | E41: PENGHITUNAGN PPh PASAL 21 | AK41: tanggungan sepenuhnya, paling banyak 3 (tiga) orang.
C42: 13. | E42: Jumlag Penghasilan Neto (8 - 12) | X42: =X35-X40 -> 283300000 | AF42: (6) Huruf A.6 | AJ42: : Diisi dengan nama jabatan penerima penghasilan.
C43: 14. | E43: Penghasilan Neto dari Pemotongan Sebelumnya | X43: 0 | AF43: (7) Huruf A.7 | AJ43: : Diisi dengan “Ya” jika penerima penghasilan
...

Sheet INDUK 1
P4: KEMENTERIAN KEUANGAN | AB4: SPT TAHUNAN | AR4: INDUK
P6: REPUBLIK INDONESIA | AB6: PAJAK PENGHASILAN (PPh)
P7: DIREKTORAT JENDERAL PAJAK
AB8: WAJIB PAJAK ORANG PRIBADI | AR8: HALAMAN 1
D11: TAHUN PAJAK/BAGIAN TAHUN PAJAK | U11: PERIODE | AB11: STATUS | AI11: SUMBER PENGHASILAN | AR11: METODE PEMBUKUAN
D13: X | E13: TAHUN PAJAK | U13: BULAN | X13: BULAN | AB13: X | AC13: NORMAL | AI13: X | AJ13: PEKERJAAN | AS13: PEMBUKUAN STELSEL AKRUAL
E15: BAGIAN TAHUN PAJAK | U15: MULAI | X15: AKHIR | AC15: PEMBETULAN | AI15: X | AJ15: KEGIATAN USAHA | AS15: PEMBUKUAN STELSEL KAS
D17: 2 | G17: 0 | K17: 2 | O17: 5 | U17: 0 | V17: 1 | W17: S.D | X17: 1 | Y17: 2 | AJ17: PEKERJAAN BEBAS | AR17: X | AS17: PENCATATAN
C23: A. | D23: IDENTITAS WAJIB PAJAK
D26: 1. | E26: NIK/NPWP | P26: 3 | Q26: 4 | R26: 0 | S26: 2 | T26: 0 | U26: 1 | V26: 1 | W26: 2 | X26: 3 | Y26: 4 | Z26: 5 | AA26: 6 | AB26: 0 | AC26: 0 | AD26: 0 | AE26: 1 | AI26: 7. | AJ26: STATUS KEWAJIBAN PERPAJAKAN SUAMI DAN ISTRI
D28: 2. | E28: NAMA | P28: Fajar | AJ28: PISAH HARTA (PH) | AR28: MEMILIH TERPISAH (MT)
D30: 3. | E30: JENIS ID | P30: X | Q30: KTP | U30: KITAS | Z30: PASPOR | AI30: (Jika status kewajiban perpajakan Anda dengan pasangan adalah PH
D32: 4. | E32: NO. ID | P32: 3402011234560001 | AI32: atau MT. Anda diwajibkan mengisi bagian ini dan Lampiran 4 Bagian B)
D34: 5. | E34: NO. TELEPON | P34: (0274) 555666 | AI34: 8. | AJ34: NIK/NPWP SUAMI/ISTRI
D36: 6. | E36: EMAIL | P36: welcome.fajar@gmail.com
C39: B. | D39: IKHTISAR PENGHASILAN NETO
D42: 1 | E42: a | I42: APAKAH ANDA MENERIMA PENGHASILAN DALAM NEGERI DARI PEKERJAAN? | AQ42: ='Lampiran 1.3'!AG59 -> 283300000
K44: Tidak. (Lanjut ke pertanyaan selanjutnya)
H46: V | K46: Ya. (Isi Lampiran 1 Bagian D lalu ke pertanyaan selanjutnya)
E48: b | I48: 1) | J48: APAKAH ANDA MENERIMA PENGHASILAN DALAM NEGERI DARI USAHA DAN/ATAU PEKERJAAN
J49: BEBAS?
K51: Tidak. (Lanjut ke pertanyaan 1c)
H53: V | K53: Ya. (Lanjut ke pertanyaan selanjutnya)
I55: 2) | J55: APAKAH ANDA TERMASUK WAJIB PAJAK ORANG PRIBADI YANG MEMILIKI PEREDARAN BRUTO
J56: TERTENTU ATAU ORANG PRIBADI PENGUSAHA TERTENTU (OPPT)
K58: Tidak. (Lanjut ke pertanyaan selanjutnya)
H60: V | K60: Ya, saya termasuk Wajib Pajak Orang Pribadi yang memiliki peredaran bruto tertentu yang dikenai pajak
K61: bersifat final. (Isi Lampiran 3B Bagian A, Lalu ke pertanyaan selanjutnya)
K63: Ya, Saya termasuk Wajib Pajak OPPT. (Isi Lampiran 3B Bagian B, lalu ke pertanyaan selanjutnya)
I65: 3) | J65: APAKAH ANDA MENGGUNAKAN NORMA DALAM MENGHITUNG PENGHASILAN NETO?
H67: V | K67: Tidak, saya menyelenggarakan pembukuan (Lanjut ke pertanyaan selanjutnya)
K69: Tidak, saya hanya menerima penghasilan dari usaha yang dikenakan pajak bersifat final dan
K70: tidak menyelenggarakan pembukuan. (Lanjut ke pertanyaan 1c)
K72: Ya, saya berhak menggunakan Norma Penghitungan Penghasilan Neto.
K73: (Isi Lampiran 1B Bagian C, Lampiran 3A-4 Bagian A, lalu ke pertanyaan 1c)
I75: 4) | J75: ANDA MENYELENGGARAKAN PEMBUKUAN. SEBUTKAN SEKTOR USAHA YANG ANDA LAKUKAN.
K77: Dagang. (Isi Lampiran 3A-1, lalu ke pertanyaan selanjutnya)
K79: Jasa. (Isi Lampiran 3A-2, lalu ke pertanyaan selanjutnya)
K81: Industri. (Isi Lampiran 3A-3, lalu ke pertanyaan selanjutnya)
I83: 5) | K83: PENGHASILAN NETO DARI USAHA DAN/ATAU PEKERJAAN BEBAS
...

Sheet INDUK 2
P4: KEMENTERIAN KEUANGAN | AB4: SPT TAHUNAN | AR4: INDUK
P6: REPUBLIK INDONESIA | AB6: PAJAK PENGHASILAN (PPh)
P7: DIREKTORAT JENDERAL PAJAK
AB8: WAJIB PAJAK ORANG PRIBADI | AR8: HALAMAN 2
C11: E. | D11: PPh KURANG/LEBIH BAYAR
D14: 11 | E14: a | I14: PPH KURANG/LEBIH BAYAR | AD14: ( | AE14: 9 | AF14: - | AG14: 10a | AH14: - | AI14: 10b | AJ14: - | AK14: 10c | AL14: + | AM14: 10d | AN14: ) | AQ14: ='INDUK 1'!AQ125-'INDUK 1'!AQ131-'INDUK 1'!AQ137-'INDUK 1'!AQ139-'INDUK 1'!AQ141 -> 1875000
E17: b | I17: APAKAH TERDAPAT SURAT KEPUTUSAN PERSETUJUAN PENGANGSURAN ATAU PENUNDAAN
I18: PEMBAYARAN PAJAK?
H20: V | K20: Tidak, saya tidak memilikinya. (Lanjut ke pertanyaan selanjutnya)
K22: Ya, saya memilikinya. (isi dengan jumlah yang telah disetujui untuk diangsur/ditunda, lalu ke
K23: pertanyaan selanjutnya)
E25: c | I25: PPh YANG MASIH HARUS DIBAYAR | AG25: ( | AH25: 11a | AI25: - | AJ25: 11b | AK25: ) | AQ25: =AQ14-AQ17 -> 1875000
C28: F. | D28: PEMBETULAN (DIISI JIKA STATUS SPT ADALAH PEMBETULAN)
D31: 12 | E31: a | I31: PPH KURANG/LEBIH BAYAR PADA SPT YANG DIBETULKAN | AH31: GANTI SPT SEBELUMNYA | AQ31: 0
E33: a | I33: PPH KURANG/LEBIH BAYAR KARENA PEMBETULAN | AG33: ( | AH33: 11a | AI33: - | AJ33: 12a | AK33: ) | AQ33: 0
C36: G. | D36: PERMOHONAN PENGEMBALIAN PPh LEBIH BAYAR (DIISI JIKA STATUS SPT ADALAH LEBIH BAYAR)
D38: PPh LEBIH BAYAR 11a atau 12b MOHON | AC38: NOMOR REKENING | AQ38: NAMA BANK
E40: Dikembalikan melalui pemeriksaan.
E42: Dikembalikan melalui permohonan pengembalian pendahuluan. | AC42: NAMA PEMILIK REKENING
C45: H. | D45: ANGSURAN PPh PASAL 25 TAHUN PAJAK BERIKUTNYA
D48: 13 | E48: a | G48: APAKAH ANDA HANYA MENERIMA PENGHASILAN TERATUR DAN BERKEWAJIBAN MEMBAYAR | AQ48: =(1/12*('INDUK 1'!AQ125-'INDUK 1'!AQ131)) -> 156250
G49: ANGSURAN PPh PASAL 25 TAHUN PAJAK BERIKUTNYA?
I51: Tidak. (Lanjut ke pertanyaan selanjutnya)
G53: V | I53: Ya, angsuran PPh Pasal 25-nya adalah | AD53: ( | AE53: 1/ | AG53: x | AH53: ( | AI53: 9 | AJ53: - | AK53: 10 | AL53: )
E55: b | G55: APAKAH ANDA MENYUSUN PERHITUNGAN TERSENDIRI ANGSURAN PPh PASAL 25 TAHUN PAJAK
G56: BERIKUTNYA?
G58: V | I58: Tidak. (Lanjut ke pertanyaan selanjutnya)
I60: Ya. (Isi lampiran 4 Bagian A)
E62: c | G62: APAKAH ANDA MEMBAYAR ANGSURAN PPH PASAL 25 OPPT TAHUN PAJAK BERIKUTNYA?
G64: V | I64: Tidak, saya tidak memiliki kewajiban untuk membayar angsuran PPh Pasal 25
I66: Ya, angsuran PPh Pasal 25 saya adalah 0,75%, dari penghasulan bruto setiap bulan dari masing masing tempat usaha
C69: I. | D69: PERNYATAAN TRANSAKSI LAINNYA
D71: 14 | E71: a | G71: HARTA PADA AKHIR TAHUN PAJAK (Isi Lampiran 1 Bagian A) | AQ71: ='Lampiran 1.2'!J96 -> 1475000000
E73: b | G73: APAKAH ANDA MEMILIKI UTANG PADA AKHIR TAHUN PAJAK | AQ73: ='Lampiran 1.2'!AB122 -> 50000000
I75: Tidak. (Lanjut ke pertanyaan selanjutnya)
G77: V | I77: Ya, (Isi Lampiran 1 Bagian B, lalu ke pertanyaan selanjutnya)
E79: c | G79: APAKAH ANDA MENERIMA PENGHASILAN YANG DIKENAKAN PAJAK PENGHASILAN BERSIFAT FINAL? | AQ79: ='Lampiran 2'!W59 -> 150000000
I81: Tidak. (Lanjut ke pertanyaan selanjutnya)
G83: V | I83: Ya, (Isi Lampiran 2 Bagian A, lalu ke pertanyaan selanjutnya)
E85: d | G85: APAKAH ANDA MENERIMA PENGHASILAN YANG TIDAK TERMASUK OBJEK PAJAK? | AQ85: ='Lampiran 2'!AJ80 -> 50000000
...

Sheet Lampiran 1.1
D5: PERHATIAN | L5: A. | M5: HARTA PADA AKHIR TAHUN PAJAK | AG5: LAMPIRAN 1
D7: LAPORAN INI DIISI OLEH WAJIB PAJAK UNTUK | L7: B. | M7: UTANG PADA AKHIR TAHUN PAJAK
D9: MELAPORKAN HARTA, UTANG, DAFTAR | L9: C. | M9: DAFTAR ANGGOTA KELUARGA YANG MENJADI TANGGUNGAN
AG10: HALAMAN 1
D11: ANGGOTA KELUARGA YANG MENJADI | L11: D. | M11: PENGHASILAN NETO DALAM NEGERI DARI PEKERJAAN
D13: TANGGUNGAN, PENGHASILAN NETO DALAM | L13: E. | M13: DAFTAR BUKTI PEMOTONGAN PEMUNGUTAN PPh
D15: NEGERI DARI PEKERJAAN, DAN ATAU BUKTI
D17: PEMOTONGAN PEMUNGUTAN PPH | L17: NIK/NPWP | N17: ='INDUK 1'!P26 -> 3 | O17: ='INDUK 1'!Q26 -> 4 | P17: ='INDUK 1'!R26 -> 0 | Q17: ='INDUK 1'!S26 -> 2 | R17: ='INDUK 1'!T26 -> 0 | S17: ='INDUK 1'!U26 -> 1 | T17: ='INDUK 1'!V26 -> 1 | U17: ='INDUK 1'!W26 -> 2 | ... AC17: ='INDUK 1'!AE26 -> 1 | AG17: TAHUN PAJAK | AJ17: ='INDUK 1'!D17 -> 2 | AK17: ='INDUK 1'!G17 -> 0 | AL17: ='INDUK 1'!K17 -> 2 | AM17: ='INDUK 1'!O17 -> 5
C20: A. | D20: HARTA PADA AKHIR TAHUN PAJAK
C22: 1. | D22: KAS DAN SETARA KAS
C24: KODE | E24: DESKRIPSI | H24: NOMOR AKUN | K24: ATAS NAMA | M24: NAMA BANK/INSTITUSI | T24: LOKASI HARTA | Z24: TAHUN PEROLEHAN | AD24: SALDO | AJ24: KETERANGAN
AJ25: (Harta PPS/HARTA INVESTASI PPS
C27: (1) | E27: (2) | H27: (3) | K27: (4) | M27: (5) | T27: (6) | Z27: (7) | AD27: (8) | AJ27: (9)
C28: 0102 | E28: TABUNGAN | H28: 1234567812354550 | K28: FAJAR | M28: BANK BCA | T28: SLEMAN | Z28: 2013 | AD28: ='SOAL KASUS'!F55 -> 300000000 | AJ28: -
C30: 0101 | E30: UANG TUNAI | H30: - | K30: - | M30: - | T30: SLEMAN | Z30: 2025 | AD30: ='SOAL KASUS'!F59 -> 50000000 | AJ30: -
C40: JUMLAH TABEL 1 | AD40: =SUM(AD28:AI39) -> 350000000
C42: 2. | D42: PIUTANG
C44: KODE | E44: DESKRIPSI | H44: LOKASI PENERIMA PINJAMAN | K44: PENERIMA PINJAMAN | R44: NILAI PIUTANG | Z44: TAHUN DIMULAI | AD44: SALDO PIUTANG SAAT INI | AJ44: KETERANGAN
AJ45: (Harta PPS/HARTA INVESTASI PPS
C47: (1) | E47: (2) | H47: (3) | K47: (4) | R47: (5) | Z47: (6) | AD47: (7) | AJ47: (8)
K48: NIK/NPWP :
K49: NAMA :
K50: NIK/NPWP :
K51: NAMA :
K52: NIK/NPWP :
K53: NAMA :
K54: NIK/NPWP :
K55: NAMA :
K56: NIK/NPWP :
K57: NAMA :
K58: NIK/NPWP :
K59: NAMA :
C60: JUMLAH TABEL 2
C62: 3. | D62: INVESTASI/SEKURITAS
C64: KODE | E64: DESKRIPSI | G64: LOKASI HARTA | J64: BANK/INSTITUSI PENERIMA INVESTASI | P64: NOMOR AKUN | V64: HARGA PEROLEHAN | AB64: TAHUN PEROLEHAN | AF64: NILAI SAAT INI | AJ64: KETERANGAN
AJ65: (Harta PPS/HARTA INVESTASI PPS
C67: (1) | E67: (2) | G67: (3) | J67: (4) | P67: (5) | V67: (6) | AB67: (7) | AF67: (8) | AJ67: (9)
C68: ='SOAL KASUS'!B56 -> 0309 | E68: =UPPER('SOAL KASUS'!C56) -> PENYERTAAN MODAL DALAM PERUSAHAAN LAIN YANG BUKAN ATAS SAHAM | G68: SLEMAN | J68: NIK/NPWP : 41234567891123456 | V68: ='SOAL KASUS'!E56 -> 175000000 | AB68: ='SOAL KASUS'!D56 -> 2018 | AF68: ='SOAL KASUS'!F56 -> 200000000
J69: NAMA : CV SEHAT SENTOSA
J70: NIK/NPWP :
...

Sheet Lampiran 1.2
D5: PERHATIAN | L5: A. | M5: HARTA PADA AKHIR TAHUN PAJAK | AG5: LAMPIRAN 1
D7: LAPORAN INI DIISI OLEH WAJIB PAJAK UNTUK | L7: B. | M7: UTANG PADA AKHIR TAHUN PAJAK
D9: MELAPORKAN HARTA, UTANG, DAFTAR | L9: C. | M9: DAFTAR ANGGOTA KELUARGA YANG MENJADI TANGGUNGAN
AG10: HALAMAN 2
D11: ANGGOTA KELUARGA YANG MENJADI | L11: D. | M11: PENGHASILAN NETO DALAM NEGERI DARI PEKERJAAN
D13: TANGGUNGAN, PENGHASILAN NETO DALAM | L13: E. | M13: DAFTAR BUKTI PEMOTONGAN PEMUNGUTAN PPh
D15: NEGERI DARI PEKERJAAN, DAN ATAU BUKTI
D17: PEMOTONGAN PEMUNGUTAN PPH | L17: NIK/NPWP | N17: ='Lampiran 1.1'!N17 -> 3 | O17: ='Lampiran 1.1'!O17 -> 4 | P17: ='Lampiran 1.1'!P17 -> 0 | Q17: ='Lampiran 1.1'!Q17 -> 2 | R17: ='Lampiran 1.1'!R17 -> 0 | S17: ='Lampiran 1.1'!S17 -> 1 | T17: ='Lampiran 1.1'!T17 -> 1 | U17: ='Lampiran 1.1'!U17 -> 2 | ... AC17: ='Lampiran 1.1'!AC17 -> 1 | AG17: TAHUN PAJAK | AJ17: ='Lampiran 1.1'!AJ17 -> 2 | AK17: ='Lampiran 1.1'!AK17 -> 0 | AL17: ='Lampiran 1.1'!AL17 -> 2 | AM17: ='Lampiran 1.1'!AM17 -> 5
C20: A. | D20: HARTA PADA AKHIR TAHUN PAJAK
C22: 5. | D22: HARTA TIDAK BERGERAK
C24: KODE | E24: DESKRIPSI | G24: LOKASI HARTA | I24: UKURAN PROPERTI | M24: SUMBER KEPEMILIKAN | P24: NOMOR SERTIFIKAT | T24: TAHUN PEROLEHAN | X24: HARGA PEROLEHAN | AE24: NILAI SAAT INI | AJ24: KETERANGAN
AJ25: (Harta PPS/HARTA INVESTASI PPS
C27: (1) | E27: (2) | G27: (3) | I27: (4) | M27: (5) | P27: (6) | T27: (7) | X27: (8) | AE27: (9) | AJ27: (10)
C28: ='SOAL KASUS'!B58 -> 0501 | E28: =UPPER('SOAL KASUS'!C58) -> TANAH KOSONG | G28: Jl. Melati, Kelurahan Sariharjo, Kecamatan Ngaglik, Kabupaten Sleman | I28: TANAH : | M28: WARISAN | P28: 325 | T28: ='SOAL KASUS'!D58 -> 2023 | X28: ='SOAL KASUS'!E58 -> 550000000 | AE28: ='SOAL KASUS'!F58 -> 900000000
I29: BANGUNAN : 0
I30: TANAH :
I31: BANGUNAN :
I32: TANAH :
I33: BANGUNAN :
I34: TANAH :
I35: BANGUNAN :
I36: TANAH :
I37: BANGUNAN :
I38: TANAH :
I39: BANGUNAN :
I40: TANAH :
I41: BANGUNAN :
C42: JUMLAH TABEL 5 | X42: =SUM(X28:AD41) -> 550000000 | AE42: =SUM(AE28:AI41) -> 900000000
C44: 6. | D44: HARTA LAINNYA
C46: KODE | E46: DESKRIPSI | G46: TAHUN PEROLEHAN | I46: BUKTI KEPEMILIKAN/NOMOR AKUN | M46: INFORMASI TAMBAHAN | V46: HARGA PEROLEHAN | AD46: NILAI SAAT INI | AJ46: KETERANGAN
AJ47: (Harta PPS/HARTA INVESTASI PPS
C49: (1) | E49: (2) | G49: (3) | I49: (4) | M49: (5) | V49: (6) | AD49: (7) | AJ49: (8)
C90: JUMLAH TABEL 6
C92: 7. | D92: IKHTISAR HARTA
C94: DESKRIPSI | J94: HARGA PEROLEHAN | V94: NILAI SAAT INI
C95: (1) | J95: (2) | V95: (3)
C96: JUMLAH HARTA PADA AKHIR TAHUN PAJAK | J96: ='Lampiran 1.1'!AD40+'Lampiran 1.1'!AD60+'Lampiran 1.1'!V80+'Lampiran 1.1'!Z118+'Lampiran 1.2'!X42+'Lampiran 1.2'!V90 -> 1475000000 | V96: ='Lampiran 1.1'!AD40+'Lampiran 1.1'!AD60+'Lampiran 1.1'!AF80+'Lampiran 1.1'!AF118+'Lampiran 1.2'!AE42+'Lampiran 1.2'!AD90 -> 1750000000
C97: JUMLAHKAN HARTA PADA TABEL 1 SAMPAI DENGAN TABEL 6 DI TABEL 7 KOLOM (2)
C98: PINDAHKAN JUMLAH HARTA TABEL 7 KOLOM (2) KE INDUK BAGIAN I ANGKA 14 HURUF a.
C100: B. | D100: UTANG PADA AKHIR TAHUN PAJAK
...

Sheet Lampiran 1.3
D5: PERHATIAN | L5: A. | M5: HARTA PADA AKHIR TAHUN PAJAK | AG5: LAMPIRAN 1
D7: LAPORAN INI DIISI OLEH WAJIB PAJAK UNTUK | L7: B. | M7: UTANG PADA AKHIR TAHUN PAJAK
D9: MELAPORKAN HARTA, UTANG, DAFTAR | L9: C. | M9: DAFTAR ANGGOTA KELUARGA YANG MENJADI TANGGUNGAN
AG10: HALAMAN 3
D11: ANGGOTA KELUARGA YANG MENJADI | L11: D. | M11: PENGHASILAN NETO DALAM NEGERI DARI PEKERJAAN
D13: TANGGUNGAN, PENGHASILAN NETO DALAM | L13: E. | M13: DAFTAR BUKTI PEMOTONGAN PEMUNGUTAN PPh
D15: NEGERI DARI PEKERJAAN, DAN ATAU BUKTI
D17: PEMOTONGAN PEMUNGUTAN PPH | L17: NIK/NPWP | N17: ='Lampiran 1.2'!N17 -> 3 | O17: ='Lampiran 1.2'!O17 -> 4 | P17: ='Lampiran 1.2'!P17 -> 0 | Q17: ='Lampiran 1.2'!Q17 -> 2 | R17: ='Lampiran 1.2'!R17 -> 0 | S17: ='Lampiran 1.2'!S17 -> 1 | T17: ='Lampiran 1.2'!T17 -> 1 | U17: ='Lampiran 1.2'!U17 -> 2 | ... AC17: ='Lampiran 1.2'!AC17 -> 1 | AG17: TAHUN PAJAK | AJ17: ='Lampiran 1.2'!AJ17 -> 2 | AK17: ='Lampiran 1.2'!AK17 -> 0 | AL17: ='Lampiran 1.2'!AL17 -> 2 | AM17: ='Lampiran 1.2'!AM17 -> 5
C20: C. | D20: DAFTAR ANGGOTA KELUARGA YANG MENJADI TANGGUNGAN
C22: NAMA | G22: NIK | L22: TANGGAL LAHIR | V22: HUBUNGAN DENGAN WAJIB PAJAK | AH22: PEKERJAAN
C25: (1) | G25: (2) | L25: (3) | V25: (4) | AH25: (5)
C26: SARAH | G26: 3405555121950002 | L26: 01 Desember 1998 | V26: ISTERI | AH26: IBU RUMAH TANGGA
C28: LILI | G28: 3405555907140001 | L28: 19 Agustus 2014 | V28: ANAK KANDUNG | AH28: PELAJAR
C30: AHMAD | G30: 3405555907160001 | L30: 19 Juli 2016 | V30: ANAK KANDUNG | AH30: PELAJAR
C43: D. | D43: PENGHASILAN NETO DALAM NEGERI DARI PEKERJAAN
C45: NO | E45: NAMA PEMBERI KERJA | I45: NOMOR IDENTITAS PEMBERI KERJA | N45: PENGHASILAN BRUTO | W45: PENGURANG PENGHASILAN BRUTO/BIAYA | AG45: PENGHASILAN NETO
C48: (1) | E48: (2) | I48: (3) | N48: (4) | W48: (5) | AG48: (6)
C49: 1 | E49: PT SEMPURNA | I49: 696115203542000 | N49: ='BP A1'!X35 -> 289900000 | W49: ='BP A1'!X40 -> 6600000 | AG49: =N49-W49 -> 283300000
C59: JUMLAH TABEL D | AG59: =SUM(AG49:AN58) -> 283300000
AA60: PINDAHKAN JUMLAH TABEL D KE INDUK BAGIAN B ANGKA 1 HURUF a.
C62: E. | D62: DAFTAR BUKTI PEMOTONGAN/PEMUNGUTAN PPh
C64: NO | E64: PEMOTONG/PEMUNGUT PPh | K64: BUKTI PEMOTONGAN/PEMUNGUTAN | S64: JENIS PAJAK | W64: PENGHASILAN BRUTO | AG64: JUMLAH PPh YANG DIPOTONG/DIPUNGUT
C67: (1) | E67: (2) | K67: (3) | S67: (4) | W67: (5) | AG67: (6)
C68: 1 | E68: NIK/NPWP : 0696115203542000 | K68: NOMOR : 2504311G5 | S68: Pasal 21 | W68: ='BP A1'!X35 -> 289900000 | AG68: ='BP A1'!X50 -> 26370000
E69: NAMA : PT SEMPURNA | K69: TANGGAL : 31 DESEMBER 2025
E70: NIK/NPWP : | K70: NOMOR :
E71: NAMA : | K71: TANGGAL :
E72: NIK/NPWP : | K72: NOMOR :
E73: NAMA : | K73: TANGGAL :
E74: NIK/NPWP : | K74: NOMOR :
E75: NAMA : | K75: TANGGAL :
E76: NIK/NPWP : | K76: NOMOR :
E77: NAMA : | K77: TANGGAL :
E78: NIK/NPWP : | K78: NOMOR :
E79: NAMA : | K79: TANGGAL :
E80: NIK/NPWP : | K80: NOMOR :
... E97: NAMA : | K97: TANGGAL :
C98: JUMLAH KREDIT PAJAK DALAM NEGERI | AG98: =SUM(AG68:AN97) -> 26370000
C99: KREDIT PAJAK ATAS PENGHASILAN DARI LUAR NEGERI (DIISI DARI LAMPIRAN 2 JUMLAH TABLE C 10) | AG99: 0
C100: JUMLAH TABEL E (16) + (17) | AG100: =AG98+AG99 -> 26370000
...

Sheet Lampiran 2
D5: PERHATIAN | L5: A. | M5: PENGHASILAN YANG DIKENAKAN PAJAK PENGHASILAN BERSIFAT FINAL | AG5: LAMPIRAN 2
D7: LAPORAN INI DIISI OLEH WAJIB PAJAK UNTUK | L7: B. | M7: PENGHASILAN YANG TIDAK TERMASUK OBJEK PAJAK
D9: MELAPORKAN PENGHASILAN YANG DIKENAKAN PPh YANG | L9: C. | M9: PENGHASILAN NETO LUAR NEGERI
D11: BERSIFAT FINAL. PENGHASILAN YANG TIDAK TERMASUK
D13: OBJEK PAJAK DAN/ATAU PENGHASILAN NETO LUAR
D15: NEGERI | L15: NIK/NPWP | N15: ='Lampiran 1.3'!N17 -> 3 | O15: ='Lampiran 1.3'!O17 -> 4 | P15: ='Lampiran 1.3'!P17 -> 0 | Q15: ='Lampiran 1.3'!Q17 -> 2 | R15: ='Lampiran 1.3'!R17 -> 0 | S15: ='Lampiran 1.3'!S17 -> 1 | T15: ='Lampiran 1.3'!T17 -> 1 | U15: ='Lampiran 1.3'!U17 -> 2 | ... AC15: ='Lampiran 1.3'!AC17 -> 1 | AG15: TAHUN PAJAK | AJ15: ='Lampiran 1.3'!AJ17 -> 2 | AK15: ='Lampiran 1.3'!AK17 -> 0 | AL15: ='Lampiran 1.3'!AL17 -> 2 | AM15: ='Lampiran 1.3'!AM17 -> 5
C19: A. | D19: PENGHASILAN YANG DIKENAKAN PAJAK PENGHASILAN BERSIFAT FINAL
C21: NO | E21: PEMOTONG/PEMUNGUT PPh | H21: KODE | J21: JENIS PENGHASILAN | W21: DASAR PENGENAAN PAJAK | AG21: PPh TERUTANG
C24: (1) | E24: (2) | H24: (3) | J24: (4) | W24: (5) | AG24: (6)
C25: 1 | E25: NIK/NPWP : 3402011234560001 | H25: ='SOAL KASUS'!B41 -> 28-402-01 | J25: ='SOAL KASUS'!C41 -> Pengalihan Hak atas Tanah dan/atau Bangunan | W25: ='SOAL KASUS'!D41 -> 150000000 | AG25: ='SOAL KASUS'!E41 -> 3750000
E26: NAMA : FAJAR
E27: NIK/NPWP :
E28: NAMA :
E29: NIK/NPWP :
E30: NAMA :
E31: NIK/NPWP :
E32: NAMA :
E33: NIK/NPWP :
E34: NAMA :
E35: NIK/NPWP :
E36: NAMA :
E37: NIK/NPWP :
... E58: NAMA :
C59: JUMLAH TABEL A | W59: =SUM(W25:AF58) -> 150000000 | AG59: =SUM(AG25:AN58) -> 3750000
O60: PINDAHKAN JUMLAH TABEL A KOLOM (5) KE INDUK BAGIAN I ANGKA 14 HURUF c.
C62: B. | D62: PENGHASILAN YANG TIDAK TERMASUK OBJEK PAJAK
C64: NO | E64: KODE | I64: JENIS PENGHASILAN | Q64: SUMBER PENGHASILAN | AJ64: PENGHASILAN BRUTO
Q66: NIK/NPWP | AA66: NAMA
C67: (1) | E67: (2) | I67: (3) | Q67: (4) | AA67: (5) | AJ67: (6)
C68: 1 | E68: ='SOAL KASUS'!B45 -> 303 | I68: ='SOAL KASUS'!C45 -> Dividen atau bagian laba | Q68: 41234567891123400 | AA68: CV Sehat Sentosa | AJ68: ='SOAL KASUS'!F45 -> 50000000
C80: JUMLAH TABEL B | AJ80: =SUM(AJ68:AN79) -> 50000000
AB81: PINDAHKAN JUMLAH TABEL B KE INDUK BAGIAN I ANGKA 14 HURUF d.
C83: C. | D83: PENGHASILAN NETO LUAR NEGERI
C85: NO | E85: SUMBER/PEMBERI PENGHASILAN | H85: TANGGAL TRANSAKSI | J85: JENIS PENGHASILAN | M85: PENGHASILAN NETO (RUPIAH) | Q85: PAJAK PENGHASILAN YANG TERUTANG/DIBAYAR/DIPOTONG DI LUAR NEGERI | AK85: KREDIT PAJAK YANG DAPAT DIPERHITUNGKAN
E87: NAMA | G87: NEGARA | Q87: NILAI DALAM MATA UANG ASING | X87: NILAI DALAM RUPIAH | AE87: MATA UANG ASING
C89: (1) | E89: (2) | G89: (3) | H89: (4) | J89: (5) | M89: (6) | Q89: (7) | X89: (8) | AE89: (9) | AK89: (10)
C102: JUMLAH TABEL C
F103: PINDAHKAN JUMLAH TABEL C KOLOM (6) KE INDUK BAGIAN B ANGKA 1 HURUF d | W103: PINDAHKAN JUMLAH TABEL C KOLOM (10) KE LAMPIRAN 1 BAGIAN E BARIS 17 KOLOM (6)

Sheet Lampiran 3A-1
D5: PERHATIAN | O5: REKONSILIASI LAPORAN KEUANGAN | AI5: LAMPIRAN 3A-1
D7: LAMPIRAN INI DIISI OLEH WAJIB PAJAK
D9: YANG MENYELENGGARAKAN PEMBUKUAN | O9: (DAGANG)
D11: STELSEL KAS ATAU PEMBUKUAN STELSEL
D13: AKRUAL DI SEKTOR USAHA DAGANG | O13: NIK/NPWP | AI13: TAHUN PAJAK
C17: A.1 | D17: LAPORAN LABA RUGI
C19: KODE AKUN | E19: NAMA AKUN | L19: NILAI KOMERSIAL | P19: TIDAK TERMASUK OBJEK PAJAK | S19: DIKENAKAN PPH FINAL | W19: OBJEK PAJAK TIDAK FINAL | AA19: PENYESUAIAN FISKAL POSITIF | AE19: PENYESUAIAN FISKAL NEGATIF | AI19: KODE PENYESUAIAN FISKAL | AM19: NILAI FISKAL
C22: (1) | E22: (2) | L22: (3) | P22: (4) | S22: (5) | W22: (6) | AA22: (7) | AE22: (8) | AI22: (9) | AM22: (10)
E23: PENJUALAN
C24: 4002 | E24: PENJUALAN DOMESTIK
C25: 4003 | E25: PENJUALAN EKSPOR
C26: 4004 | E26: PENJUALAN BRUTO
E27: DIKURANGI
C28: 4011 | E28: RETUR
C29: 4012 | E29: POTONGAN PENJUALAN
C30: 4020 | E30: PENJUALAN BERSIH
E31: HARGA POKOK PENJUALAN:
C32: 5001 | E32: PEMBELIAN
C33: 5008 | E33: PERSEDIAAN AWAL
C34: 5009 | E34: DIKURANGI: PERSEDIAAN AKHIR
C35: 5020 | E35: JUMLAH HARGA POKOK PENJUALAN
C36: 4300 | E36: LABA KOTOR
E37: BEBAN USAHA
C38: 5311 | E38: BEBAN GAJI, TUNJANGAN, BONUS, HONORARIUM, THR, DLL
C39: 5313 | E39: BEBAN TRANSPORTASI
C40: 5314 | E40: BEBAN PENYUSUTAN DAN AMORTISASI
C41: 5315 | E41: BEBAN SEWA
C42: 5316 | E42: BEBAN BUNGA
C43: 5317 | E43: BEBAN SEHUBUNGAN DENGAN JASA
C44: 5318 | E44: BEBAN PIUTANG TIDAK TERTAGIH
C45: 5320 | E45: BEBAN PROMOSI/PEMASARAN
C46: 5321 | E46: BEBAN ENTERTAINMENT
C47: 5322 | E47: BEBAN UMUM DAN ADMINISTRASI
C48: 5399 | E48: BEBAN USAHA LAINNYA
C49: 5400 | E49: JUMLAH BEBAN USAHA
C50: 4800 | E50: LABA (RUGI) SEBELUM PAJAK
W51: PINDAHKAN LABA (RUGI) SEBELUM PAJAK KOLOM (10) KE INDUK BAGIAN B ANGKA 1 HURUF b
C53: A.2 | D53: LAPORAN POSISI KEUANGAN (NERACA)
C55: KODE AKUN | E55: AKUN | W55: KODE AKUN | Y55: AKUN
C57: (1) | E57: (2) | W57: (1) | Y57: (2)
...

Sheet Lampiran 3A-2
D5: PERHATIAN | O5: REKONSILIASI LAPORAN KEUANGAN | AI5: LAMPIRAN 3A-2
D7: LAMPIRAN INI DIISI OLEH WAJIB PAJAK
D9: YANG MENYELENGGARAKAN PEMBUKUAN | O9: (JASA)
D11: STELSEL KAS ATAU PEMBUKUAN STELSEL
D13: AKRUAL DI SEKTOR USAHA JASA | O13: NIK/NPWP | AI13: TAHUN PAJAK
C17: A.1 | D17: LAPORAN LABA RUGI
C19: KODE AKUN | E19: NAMA AKUN | L19: NILAI KOMERSIAL | P19: TIDAK TERMASUK OBJEK PAJAK | S19: DIKENAKAN PPH FINAL | W19: OBJEK PAJAK TIDAK FINAL | AA19: PENYESUAIAN FISKAL POSITIF | AE19: PENYESUAIAN FISKAL NEGATIF | AI19: KODE PENYESUAIAN FISKAL | AM19: NILAI FISKAL
C22: (1) | E22: (2) | L22: (3) | P22: (4) | S22: (5) | W22: (6) | AA22: (7) | AE22: (8) | AI22: (9) | AM22: (10)
E23: PENDAPATAN
C24: 4021 | E24: PENDAPATAN JASA
C25: 5020 | E25: BIAYA POKOK JASA
C26: 4300 | E26: LABA KOTOR
E27: BEBAN USAHA
C28: 5311 | E28: BEBAN GAJI, TUNJANGAN, BONUS, HONORARIUM, THR, DLL
C29: 5313 | E29: BEBAN TRANSPORTASI
C30: 5314 | E30: BEBAN PENYUSUTAN DAN AMORTISASI
C31: 5315 | E31: BEBAN SEWA
C32: 5316 | E32: BEBAN BUNGA
C33: 5317 | E33: BEBAN SEHUBUNGAN DENGAN JASA
C34: 5318 | E34: BEBAN PIUTANG TIDAK TERTAGIH
C35: 5320 | E35: BEBAN PROMOSI/PEMASARAN
C36: 5321 | E36: BEBAN ENTERTAINMENT
C37: 5322 | E37: BEBAN UMUM DAN ADMINISTRASI
C38: 5399 | E38: BEBAN USAHA LAINNYA
C39: 5400 | E39: JUMLAH BEBAN USAHA
C40: 4800 | E40: LABA (RUGI) SEBELUM PAJAK
W41: PINDAHKAN LABA (RUGI) SEBELUM PAJAK KOLOM (10) KE INDUK BAGIAN BANGKA 1 HURUF b
C43: A.2 | D43: LAPORAN POSISI KEUANGAN (NERACA)
C45: KODE AKUN | E45: AKUN | W45: KODE AKUN | Y45: AKUN
C47: (1) | E47: (2) | W47: (1) | Y47: (2)
E48: ASET LANCAR | Y48: LIABILITAS JANGKA PENDEK
C49: 1101 | E49: KAS DAN SETARA KAS | W49: 2102 | Y49: UTANG USAHA - PIHAK KETIGA
C50: 1200 | E50: INVESTASI | W50: 2103 | Y50: UTANG USAHA - PIHAK YANG MEMPUNYAI HUBUNGAN ISTIMEWA
C51: 1122 | E51: PIUTANG USAHA - PIHAK KETIGA | W51: 2111 | Y51: UTANG BUNGA
C52: 1123 | E52: PIUTANG USAHA - PIHAK YANG MEMPUNYAI HUBUNGAN ISTIMEWA | W52: 2191 | Y52: UTANG PAJAK
C53: 1124 | E53: PIUTANG LAINNYA - PIHAK KETIGA | W53: 2192 | Y53: UTANG DIVIDEN
C54: 1125 | E54: PIUTANG LAINNYA - PIHAK YANG MEMPUNYAI HUBUNGAN ISTIMEWA | W54: 2195 | Y54: BEBAN YANG MASIH HARUS DIBAYAR
C55: 1131 | E55: DIKURANGI: CADANGAN PIUTANG TAK TERTAGIH | W55: 2201 | Y55: UTANG BANK JANGKA PENDEK
C56: 1401 | E56: PERSEDIAAN | W56: 2202 | Y56: UTANG JANGKA PANJANG YANG JATUH TEMPO DALAM SATU TAHUN
C57: 1421 | E57: BEBAN DIBAYAR DI MUKA | W57: 2203 | Y57: UANG MUKA
...

Sheet Lampiran 3A-3
D5: PERHATIAN | O5: REKONSILIASI LAPORAN KEUANGAN | AI5: LAMPIRAN 3A-1
D7: LAMPIRAN INI DIISI OLEH WAJIB PAJAK
D9: YANG MENYELENGGARAKAN PEMBUKUAN | O9: (INDUSTRI)
D11: STELSEL KAS ATAU PEMBUKUAN STELSEL
D13: AKRUAL DI SEKTOR USAHA INDUSTRI | O13: NIK/NPWP | AI13: TAHUN PAJAK
C17: A.1 | D17: LAPORAN LABA RUGI
C19: KODE AKUN | E19: NAMA AKUN | L19: NILAI KOMERSIAL | P19: TIDAK TERMASUK OBJEK PAJAK | S19: DIKENAKAN PPh FINAL | W19: OBJEK PAJAK TIDAK FINAL | AA19: PENYESUAIAN FISKAL POSITIF | AE19: PENYESUAIAN FISKAL NEGATIF | AI19: KODE PENYESUAIAN FISKAL | AM19: NILAI FISKAL
C22: (1) | E22: (2) | L22: (3) | P22: (4) | S22: (5) | W22: (6) | AA22: (7) | AE22: (8) | AI22: (9) | AM22: (10)
E23: PENJUALAN
C24: 4002 | E24: PENJUALAN DOMESTIK
C25: 4003 | E25: PENJUALAN EKSPOR
C26: 4004 | E26: PENJUALAN BRUTO
E27: DIKURANGI
C28: 4011 | E28: RETUR
C29: 4012 | E29: POTONGAN PENJUALAN
C30: 4020 | E30: PENJUALAN BERSIH
C31: 5040 | E31: BIAYA BAHAN BAKU
C32: 5050 | E32: BIAYA TENAGA KERJA LANGSUNG
E33: BIAYA PABRIKASI
C34: 5051 | E34: BIAYA TENAGA KERJA TIDAK LANGSUNG
C35: 5052 | E35: BIAYA PEMELIHARAAN DAN PERBAIKAN MESIN
C36: 5058 | E36: BIAYA PENYUSUTAN DAN AMORTISASI
C37: 5059 | E37: BIAYA UTILITAS
C38: 5069 | E38: BIAYA PABRIKASI LAINNYA
C39: 5070 | E39: JUMLAH BIAYA PABRIKASI
C40: 5080 | E40: JUMLAH BIAYA PRODUKSI
C41: 5090 | E41: PERSEDIAAN AWAL BARANG DALAM PROSES
C42: 5099 | E42: DIKURANGI: PERSEDIAAN AKHIR BARANG DALAM PROSES
C43: 5100 | E43: JUMLAH HARGA POKOK PRODUKSI
C44: 5008 | E44: PERSEDIAAN AWAL BARANG JADI
C45: 5009 | E45: DIKURANGI: PERSEDIAAN AKHIR BARANG JADI
... C47: 4300 | E47: LABA KOTOR
E48: BEBAN USAHA
C49: 5311 | E49: BEBAN GAJI, TUNJANGAN, BONUS, HONORARIUM, THR, DLL
C50: 5313 | E50: BEBAN TRANSPORTASI
C51: 5314 | E51: BEBAN PENYUSUTAN DAN AMORTISASI
C52: 5315 | E52: BEBAN SEWA
C53: 5316 | E53: BEBAN BUNGA
C54: 5317 | E54: BEBAN SEHUBUNGAN DENGAN JASA
C55: 5318 | E55: BEBAN PIUTANG TIDAK TERTAGIH
...

Sheet Lampiran 3A-4
D5: PERHATIAN | O5: A. | P5: PENGHASILAN NETO DALAM NEGERI DARI USAHA DAN/ATAU PEKERJAAN | AI5: LAMPIRAN 3A-4
D7: LAMPIRAN INI DIISI OLEH WAJIB PAJAK | P7: BEBAS BERDASARKAN PENCATATAN
D9: YANG MENYELENGGARAKAN PENCATATAN | O9: B. | P9: PENGHASILAN NETO DALAM NEGERI LAINNYA
D11: DAN/ATAU MEMILIKI PENGHASILAN NETO
D13: DALAM NEGERI LAINNYA | O13: NIK/NPWP | R13: ='Lampiran 1.1'!N17 -> 3 | S13: ='Lampiran 1.1'!O17 -> 4 | T13: ='Lampiran 1.1'!P17 -> 0 | U13: ='Lampiran 1.1'!Q17 -> 2 | V13: ='Lampiran 1.1'!R17 -> 0 | W13: ='Lampiran 1.1'!S17 -> 1 | X13: ='Lampiran 1.1'!T17 -> 1 | Y13: ='Lampiran 1.1'!U17 -> 2 | ... AG13: ='Lampiran 1.1'!AC17 -> 1 | AI13: TAHUN PAJAK | AL13: ='Lampiran 1.1'!AJ17 -> 2 | AM13: ='Lampiran 1.1'!AK17 -> 0 | AN13: ='Lampiran 1.1'!AL17 -> 2 | AO13: ='Lampiran 1.1'!AM17 -> 5
C17: A. | D17: PENGHASILAN NETO DALAM NEGERI DARI USAHA DAN/ATAU PEKERJAAN BEBAS BERDASARKAN PENCATATAN
C19: NO | E19: NAMA TEMPAT KEGIATAN USAHA (TKU) | L19: JENIS USAHA / PEKERJAAN BEBAS | T19: PEREDARAN BRUTO | AB19: NORMA (%) | AJ19: PENGHASILAN NETO
C21: (1) | E21: (2) | L21: (3) | T21: (4) | AB21: (5) | AJ21: (6)
C46: JUMLAH TABEL A
AA47: PINDAHKAN JUMLAH TABEL A.6 KE INDUK BAGIAN B ANGKA 1 HURUF b
C49: B. | D49: PENGHASILAN NETO DALAM NEGERI LAINNYA
C51: NO | E51: KODE | N51: JENIS PENGHASILAN | AE51: PENGHASILAN NETO
C53: (1) | E53: (2) | N53: (3) | AE53: (4)
C54: 1 | E54: 302 | N54: Sewa harta selain tanah dan/atau bangunan | AE54: ='SOAL KASUS'!F49 -> 12500000
C92: JUMLAH TABEL B | AE92: =SUM(AE54:AP91) -> 12500000
AB93: PINDAHKAN JUMLAH TABEL B KE INDUK BAGIAN B ANGKA 1 HURUF c

Sheet Lampiran 3B
D5: PERHATIAN | Z5: REKAPITULASI PEREDARAN BRUTO | AX5: LAMPIRAN 3B
D7: LAMPIRAN INI DIISI OLEH WAJIB PAJAK YANG BERKEWAJIBAN
D9: MELAPORKAN RINCIAN REKAPITULASI PEREDARAN BRUTO
Z13: NIK/NPWP | AC13: ='Lampiran 1.1'!N17 -> 3 | AD13: ='Lampiran 1.1'!O17 -> 4 | AE13: ='Lampiran 1.1'!P17 -> 0 | AF13: ='Lampiran 1.1'!Q17 -> 2 | AG13: ='Lampiran 1.1'!R17 -> 0 | AH13: ='Lampiran 1.1'!S17 -> 1 | AI13: ='Lampiran 1.1'!T17 -> 1 | AJ13: ='Lampiran 1.1'!U17 -> 2 | ... AQ13: ='Lampiran 1.1'!AB17 -> 0 | AX13: TAHUN PAJAK | BB13: ='Lampiran 1.1'!AJ17 -> 2 | BC13: ='Lampiran 1.1'!AK17 -> 0 | BD13: ='Lampiran 1.1'!AL17 -> 2 | BE13: ='Lampiran 1.1'!AM17 -> 5
C17: DAFTAR TEMPAT KEGIATAN USAHA (TKU)
C19: NO | E19: ID TKU | J19: NAMA TKU | O19: ALAMAT | AE19: KELURAHAN/DESA | AL19: KECAMATAN | AS19: KOTA/KABUPATEN | AZ19: PROVINSI
C21: (1) | E21: (2) | J21: (3) | O21: (4) | AE21: (5) | AL21: (6) | AS21: (7) | AZ21: (8)
C22: 1 | E22: 3402011234560001000000 | J22: TOKO ELEKTRONIK "WELCOME" | O22: Jl. Melati | AE22: Sariharjo | AL22: Ngaglik | AS22: Sleman | AZ22: Daerah Istimewa Yogyakarta
C29: A. | D29: REKAPITULASI PERBEDAAN BRUTO UNTUK WAJIB PAJAK ORANG PRIBADI YANG MEMILIKI PEREDARAN BRUTO TERTENTU YANG DIKENAI PAJAK BERSIFAT FINAL
C31: NO | D31: NAMA TKU | K31: JANUARI | O31: FEBRUARI | S31: MARET | W31: APRIL | AA31: MEI | AE31: JUNI | AI31: JULI | AM31: AGUSTUS | AQ31: SEPTEMBER | AU31: OKTOBER | AY31: NOVEMBER | BC31: DESEMBER | BG31: JUMLAH
C33: (1) | D33: (2) | K33: (3) | O33: (4) | S33: (5) | W33: (6) | AA33: (7) | AE33: (8) | AI33: (9) | AM33: (10) | AQ33: (11) | AU33: (12) | AY33: (13) | BC33: (14) | BG33: (15)
C34: 1 | D34: Penghasilan Toko Elektronik | K34: ='SOAL KASUS'!C20 -> 190000000 | O34: ='SOAL KASUS'!C21 -> 200000000 | S34: ='SOAL KASUS'!C22 -> 175000000 | W34: ='SOAL KASUS'!C23 -> 300000000 | AA34: ='SOAL KASUS'!C24 -> 250000000 | AE34: ='SOAL KASUS'!C25 -> 235000000 | AI34: ='SOAL KASUS'!C26 -> 260000000 | AM34: ='SOAL KASUS'!C27 -> 180000000 | AQ34: ='SOAL KASUS'!C28 -> 175000000 | AU34: ='SOAL KASUS'!C29 -> 233000000 | AY34: ='SOAL KASUS'!C30 -> 215000000 | BC34: ='SOAL KASUS'!C31 -> 301000000 | BG34: =SUM(K34:BF35) -> 2714000000
C40: a. JUMLAH PEREDARAN BRUTO | K40: =SUM(K34:N39) -> 190000000 | O40: =SUM(O34:R39) -> 200000000 | S40: =SUM(S34:V39) -> 175000000 | W40: =SUM(W34:Z39) -> 300000000 | AA40: =SUM(AA34:AD39) -> 250000000 | AE40: =SUM(AE34:AH39) -> 235000000 | AI40: =SUM(AI34:AL39) -> 260000000 | AM40: =SUM(AM34:AP39) -> 180000000 | AQ40: =SUM(AQ34:AT39) -> 175000000 | AU40: =SUM(AU34:AX39) -> 233000000 | AY40: =SUM(AY34:BB39) -> 215000000 | BC40: =SUM(BC34:BF39) -> 301000000 | BG40: =SUM(K40:BF42) -> 2714000000
C43: b. AKUMULASI PEREDARAN BRUTO | K43: =K40 -> 190000000 | O43: =K40+O40 -> 390000000 | S43: =O43+S40 -> 565000000 | W43: =S43+W40 -> 865000000 | AA43: =W43+AA40 -> 1115000000 | AE43: =AA43+AE40 -> 1350000000 | AI43: =AE43+AI40 -> 1610000000 | AM43: =AI43+AM40 -> 1790000000 | AQ43: =AM43+AQ40 -> 1965000000 | AU43: =AQ43+AU40 -> 2198000000 | AY43: =AU43+AY40 -> 2413000000 | BC43: =AY43+BC40 -> 2714000000 | BG43: =BC43 -> 2714000000
C46: c. PEREDARAN BRUTO TIDAK KENA PAJAK | AG46: 500000000 | BG46: =AG46 -> 500000000
C49: d. PEREDARAN BRUTO KENA PAJAK | K49: 0 | O49: 0 | S49: =S40 -> 175000000 | W49: =W40 -> 300000000 | AA49: =AA40 -> 250000000 | AE49: =AE40 -> 235000000 | AI49: =AI40 -> 260000000 | AM49: =AM40 -> 180000000 | AQ49: =AQ40 -> 175000000 | AU49: =AU40 -> 233000000 | AY49: =AY40 -> 215000000 | BC49: =BC40 -> 301000000 | BG49: =SUM(K49:BF51) -> 2324000000
C52: e. JUMLAH PPh FINAL TERUTANG (0,5% x d) | K52: =K49*0.5% -> 0 | O52: =O49*0.5% -> 0 | S52: =S49*0.5% -> 875000 | W52: =W49*0.5% -> 1500000 | AA52: =AA49*0.5% -> 1250000 | AE52: =AE49*0.5% -> 1175000 | AI52: =AI49*0.5% -> 1300000 | AM52: =AM49*0.5% -> 900000 | AQ52: =AQ49*0.5% -> 875000 | AU52: =AU49*0.5% -> 1165000 | AY52: =AY49*0.5% -> 1075000 | BC52: =BC49*0.5% -> 1505000 | BG52: =SUM(K52:BF54) -> 11620000
C55: f. JUMLAH PPh FINAL YANG DISETOR SENDIRI | S55: ='SOAL KASUS'!D72 -> 325000 | W55: ='SOAL KASUS'!D73 -> 1500000 | AA55: ='SOAL KASUS'!D74 -> 1250000 | AE55: ='SOAL KASUS'!D75 -> 1175000 | AI55: ='SOAL KASUS'!D76 -> 1300000 | AM55: ='SOAL KASUS'!D77 -> 900000 | AQ55: ='SOAL KASUS'!D78 -> 875000 | AU55: ='SOAL KASUS'!D79 -> 1165000 | AY55: ='SOAL KASUS'!D80 -> 1075000 | BC55: ='SOAL KASUS'!D81 -> 1505000 | BG55: =SUM(K55:BF57) -> 11070000
C58: g. JUMLAH PPh FINAL YANG DIPOTONG/DIPUNGUT PIHAK LAIN | K58: 0 | O58: 0 | S58: 0 | W58: 0 | AA58: 0 | AE58: 0 | AI58: 0 | AM58: 0 | AQ58: 0 | AU58: 0 | AY58: 0 | BC58: 0 | BG58: =SUM(K58:BF60) -> 0
C61: h. SELISIH (e-f-g) | K61: =K52-K55-K58 -> 0 | O61: =O52-O55-O58 -> 0 | S61: =S52-S55-S58 -> 550000 | W61: =W52-W55-W58 -> 0 | AA61: =AA52-AA55-AA58 -> 0 | AE61: =AE52-AE55-AE58 -> 0 | AI61: =AI52-AI55-AI58 -> 0 | AM61: =AM52-AM55-AM58 -> 0 | AQ61: =AQ52-AQ55-AQ58 -> 0 | AU61: =AU52-AU55-AU58 -> 0 | AY61: =AY52-AY55-AY58 -> 0 | BC61: =BC52-BC55-BC58 -> 0 | BG61: =SUM(K61:BF63) -> 550000
C64: i. SELISIH PADA SPT DIBETULKAN
C67: j. SELISISH KARENA PEMBETULAN (h-i)
L70: PINDAHKAN HURUF f. JUMLAH PPh FINAL YANG DISETOR SENDIRI KOLOM (15) KE LAMPIRAN 2 BAGIAN A DENGAN KODE 28-423-99 JENIS PENGHASILAN "PENGHASILAN YANG DIKENAKAN PAJAK BERSIFAT FINAL SESUAI PERATURAN PEMERINTAH NOMOR 55 TAHUN 2022 (DISETOR SENDIRI)"
AA71: PINDAHKAN HURUF g. JUMLAH PPh FINAL YANG DIPOTONG/DIPUNGUT PIHAK LAIN PADA KOLOM (3) SAMPAI (14) KE LAMPIRAN 2 BAGIAN A SESUAI DENGAN BUKTI PEMOTONGAN/PEMUNGUTAN PPh
C73: B. | D73: REKAPITULASI PEREDARAN BRUTO UNTUK WAJB PAJAK ORANG PRIBADI PENGUSAHA TERTENTU (OPPT)
D76: METODE PEMBUKUAN | L76: 1. PENCATATAN | S76: 2. PEMBUKUAN STELSEL KAS ATAS PEMBUKUAN STELSEL AKRUAL
C78: NO | D78: NAMA TKU | G78: METODE PEMBUKUAN | K78: JANUARI | O78: FEBRUARI | S78: MARET | W78: APRIL | AA78: MEI | AE78: JUNI | AI78: JULI | AM78: AGUSTUS | AQ78: SEPTEMBER | AU78: OKTOBER | AY78: NOVEMBER | BC78: DESEMBER | BG78: JUMLAH
C81: (1) | D81: (2) | G81: (3) | K81: (4) | O81: (5) | S81: (6) | W81: (7) | AA81: (8) | AE81: (9) | AI81: (10) | AM81: (11) | AQ81: (12) | AU81: (13) | AY81: (14) | BC81: (15) | BG81: (16)
C86: JUMLAH PEREDARAN BRUTO
C87: JUMLAH PPH
C89: C. | D89: REKAPITULASI PEREDARAN BRUTO UNTUK PENGGUNA NORMA PENGHITUNGAN PENGHASILAN NETO (NPPN)
D90: JIKA METODE PEMBUKUAN ADALAH 1. PENCATATAN, PINDAHKAN SELURUH DATA PADA MASING-MASING TKU DARI KOLOM (1) SAMPAI KOLOM (16) PADA TABEL B KE TABEL C LAMPIRAN INI. BARIS JUMLAH PPh PADA KOLOM (4) SAMPAI KOLOM (16) DIGABUNGKAN DENGAN JUMLAH PPh PADA TABEL C BARIS JUMLAH PPh SESUAI DENGAN KOLOM MASING-MASING
P91: JIKA METODE PEMBUKUAN ADALAH 2. PEMBUKUAN STELSEL KAS ATAU PEMBUKUAN STELSEL AKRUAL, PINDAHKAN JUMLAH PEREDARAN BRUTO KOLOM (16) KE LAMPIRAN 3A-1/3A-2/3A-3 BAGIAN A.1 DAN JUMLAH PPh KOLOM (16) KE INDUK BAGIAN D ANGKA 10 HURUF b
C92: NO | D92: NAMA TKU | G92: JENIS USAHA/PEKERJAAN BEBAS | K92: JANUARI | O92: FEBRUARI | S92: MARET | W92: APRIL | AA92: MEI | AE92: JUNI | AI92: JULI | AM92: AGUSTUS | AQ92: SEPTEMBER | AU92: OKTOBER | AY92: NOVEMBER | BC92: DESEMBER | BG92: JUMLAH
C95: (1) | D95: (2) | G95: (3) | K95: (4) | O95: (5) | S95: (6) | W95: (7) | AA95: (8) | AE95: (9) | AI95: (10) | AM95: (11) | AQ95: (12) | AU95: (13) | AY95: (14) | BC95: (15) | BG95: (16)
C100: JUMLAH PEREDARAN BRUTO
C101: JUMLAH PPH
W102: PINDAHKAN NAMA TKU KOLOM (2). JENIS USAHA/PEKERJAAN BEBAS KOLOM (3). DAN JUMLAH PEREDARAN BRUTO KOLOM (16) KE LAMPIRAN 3A-4 BAGIAN A DAN JUMLAH PPh KOLOM (16) KE INDUK BAGIAN D ANGKA 10 HURUF b

Sheet Lampiran 3C
D5: PERHATIAN | W5: DAFTAR PENYUSUTAN DAN AMORTISASI FISKAL | AX5: LAMPIRAN 3C
D7: LAMPIRAN INI DIISI OLEH WAJIB PAJAK YANG
D9: MEMBEBANKAN BIAYA PENYUSUTAN
D11: DAN/ATAU AMORTISASI
W13: NIK/NPWP | AX13: TAHUN PAJAK
C16: KODE HARTA | E16: KELOMPOK / JENIS HARTA | O16: BULAN/TAHUN PEROLEHAN | U16: HARGA PEROLEHAN (RUPIAH) | AD16: NILAI SISA BUKU FISKAL AWAL TAHUN (RUPIAH) | AK16: METODE PENYUSUTAN / AMORTISASI | AS16: PENYUSUTAN / AMORTISASI FISKAL PADA TAHUN INI (RUPIAH) | AZ16: KETERANGAN
AK18: KOMERSIAL | AO18: FISKAL
C19: (1) | E19: (2) | O19: (3) | U19: (4) | AD19: (5) | AK19: (6) | AO19: (7) | AS19: (8) | AZ19: (9)
E20: I. | F20: HARTA BERWUJUD
F21: A. | G21: KELOMPOK 1
G22: 1. | H22: ….....................................................
G23: 2. | H23: ….....................................................
G24: 3. | H24: ….....................................................
F25: B. | G25: KELOMPOK 2
G26: 1. | H26: ….....................................................
G27: 2. | H27: ….....................................................
G28: 3. | H28: ….....................................................
F29: C. | G29: KELOMPOK 3
G30: 1. | H30: ….....................................................
G31: 2. | H31: ….....................................................
G32: 3. | H32: ….....................................................
F33: D. | G33: KELOMPOK 4
G34: 1. | H34: ….....................................................
G35: 2. | H35: ….....................................................
G36: 3. | H36: ….....................................................
F37: E. | G37: KELOMPOK LAINNYA
G38: 1. | H38: ….....................................................
G39: 2. | H39: ….....................................................
G40: 3. | H40: ….....................................................
E41: II. | F41: BANGUNAN
F42: A. | G42: PERMANEN
G43: 1. | H43: ….....................................................
G44: 2. | H44: ….....................................................
G45: 3. | H45: ….....................................................
F46: B. | G46: TIDAK PERMANEN
G47: 1. | H47: ….....................................................
G48: 2. | H48: ….....................................................
C49: A. | D49: JUMLAH PENYUSUTAN FISKAL
C50: B. | D50: JUMLAH PENYUSUTAN KOMERSIAL
C51: C. | D51: SELISIH PENYUSUTAN (A-B)
...

Sheet Lampiran 3D
D5: PERHATIAN
D7: LAMPIRAN INI DIISI OLEH WAJIB PAJAK YANG | O7: RINCIAN BIAYA TERTENTU | AI7: LAMPIRAN 3D
D9: MEMBEBANKAN BIAYA ENTERTAINMENT, BIAYA
D11: PROMOSI DAN PENJUALAN, SERTA
D13: PENGGANTIAN ATAU IMBALAN DALAM BENTUK
D15: NATURA DAN/ATAU KENIKMATAN, DAN/ATAU
D17: DAFTAR PIUTANG YANG NYATA-NYATA TIDAK | O17: NIK/NPWP | AI17: TAHUN PAJAK
D19: DAPAT DITAGIH
C22: A. | D22: DAFTAR NOMINATIF BIAYA ENTERTAINMENT
C24: NO | E24: PEMBERIAN ENTERTAINMENT | W24: RELASI USAHA YANG DIBERIKAN ENTERTAINMENT | AL24: KETERANGAN
E25: TANGGAL | H25: NAMA TEMPAT | K25: ALAMAT | P25: JENIS | S25: JUMLAH | W25: NAMA | AA25: POSISI | AD25: NAMA PERUSAHAAN | AH25: JENIS USAHA
C27: (1) | E27: (2) | H27: (3) | K27: (4) | P27: (5) | S27: (6) | W27: (7) | AA27: (8) | AD27: (9) | AH27: (10) | AL27: (11)
C44: B. | D44: DAFTAR NOMINATIF BIAYA PROMOSI SERTA PENGGANTIAN ATAU IMBALAN DALAM BENTUK NATURA DAN/ATAU KENIKMATAN
C46: NO | E46: DATA PENERIMA | AH46: PEMOTONGAN/PEMUNGUT PPH
E47: NOMOR IDENTITAS | L47: NAMA | P47: ALAMAT | T47: TANGGAL | W47: BENTUK DAN JENIS BIAYA | Z47: NILAI | AD47: KETERANGAN | AH47: JUMLAH | AM47: NOMOR BUKTI POTONG
C49: (1) | E49: (2) | L49: (3) | P49: (4) | T49: (5) | W49: (6) | Z49: (7) | AD49: (8) | AH49: (9) | AM49: (10)
C70: C. | D70: DAFTAR PIUTANG YANG NYATA-NYATA TIDAK DAPAT DITAGIH
C72: NO | E72: NOMOR IDENTITAS | L72: NAMA DEBITUR | P72: ALAMAT | U72: JUMLAH PLAFON PIUTANG | AA72: JUMLAH PIUTANG YANG NYATA-NYATA TIDAK DAPAT DITAGIH | AF72: METODE PEMBEBANAN | AK72: JENIS DOKUMEN PEMBUKTIAN PEMENUHAN PERSYARATAN
C75: (1) | E75: (2) | L75: (3) | P75: (4) | U75: (5) | AA75: (6) | AF75: (7) | AK75: (8)

Sheet Lampiran 4
D5: PERHATIAN
D7: LAMPIRAN INI DIISI OLEH WAJIB PAJAK YANG | P7: A. | Q7: PENGHITUNGAN ANGSURAN PPh PASAL 25 TAHUN PAJAK BERIKUTNYA | AI7: LAMPIRAN 4
D9: BERKEWAJIBAN MEMBAYAR ANGSURAN PPh | P9: B. | Q9: PENGHITUNGAN PPh TERUTANG WAJIB PAJAK DAN SUAMI/ISTRI
D11: PASAL 25 DAN/ATAU WAJIB PAJAK YANG
D13: STATUS KEWAJIBAN PAJAK WAJIB PAJAK DAN
D15: PASANGANNYA ADALAH PISAH HARTA (PH) | O15: NIK/NPWP | AI15: TAHUN PAJAK
D17: ATAU MEMILIH TERPISAH (MT)
C20: A. | D20: PENGHITUNGAN ANGSURAN PPh PASAL 25 TAHUN PAJAK BERIKUTNYA
D23: 1 | F23: PENGHASILAN NETO
D25: 2 | F25: KOMPENSASI KERUGIAN TAHUN PAJAK BERIKUTNYA
D27: 3 | F27: ZAKAT/SUMBANGAN KEAGAMAAN YANG BERSIFAT WAJIB
D29: 4 | F29: JUMLAH PENGHASILAN NETO | T29: ( | U29: 1 | V29: - | W29: 2 | X29: - | Y29: 3 | Z29: )
D31: 5 | F31: PENGHASILAN TIDAK KENA PAJAK
D33: 6 | F33: PENGHASILAN KENA PAJAK | T33: ( | U33: 4 | V33: - | W33: 5 | X33: )
D35: 7 | F35: PPh TERUTANG
D37: 8 | F37: PENGURANG PPh TERUTANG
D39: 9 | F39: KREDIT PAJAK
D41: 10 | F41: PPh YANG HARUS DIBAYAR | T41: ( | U41: 7 | V41: - | W41: 8 | X41: - | Y41: 9 | Z41: )
D43: 11 | F43: ANGSURAN PPh PASAL 25 TAHUN PAJAK BERIKUTNYA | T43: ( | U43: 1 | V43: \ | W43: 12 | X43: - | Y43: 10 | Z43: )
M45: PINDAHKAN JUMLAH ANGSURAN PPh PASAL 25 TAHUN PAJAK BERIKUTNYA PADA NOMOR 11 KE INDUK BAGIAN H ANGKA 13 HURUF b
C47: B. | D47: PENGHITUNGAN PPh TERUTANG WAJIB PAJAK DAN SUAMI/ISTRI
AE50: WAJIB PAJAK | AK50: SUAMI/ISTRI
D52: 1 | F52: PENGHASILAN BRUTO
D54: 2 | F54: PENGHASILAN NETO
D56: 3 | F56: PENGHASILAN NETO SETELAH DIKURANGI ZAKAT/SUMBANGAN KEAGAMAAN WAJIB DAN | AD56: 3a | AJ56: 3b
F58: KOMPENSASI KERUGIAN
D60: 4 | F60: PENGHASILAN NETO SETELAH DIKURANGI ZAKAT/SUMBANGAN KEAGAMAAN WAJIB DAN
F62: KOMPENSASI KERUGIAN GABUNGAN
D64: 5 | F64: PENGHASILAN TIDAK KENA PAJAK GABUNGAN
D66: 6 | F66: PENGHASILAN KENA PAJAK GABUNGAN | T66: ( | U66: 4 | V66: - | W66: 5 | X66: )
D68: 7 | F68: PPh TERUTANG GABUNGAN
D70: 8 | F70: PPh TERUTANG YANG DITANGGUNG OLEH WAJIB PAJAK | T70: [( | U70: 3a | V70: : | W70: 4 | X70: ) x | Y70: 7 | Z70: ]
D72: 9 | F72: PPh TERUTANG YANG DITANGGUNG OLEH SUAMI/ISTRI | T72: [( | U72: 3b | V72: : | W72: 4 | X72: ) x | Y72: 7 | Z72: ]
L74: PINDAHKAN JUMLAH PPh TERUTANG YANG DITANGGUNG OLEH WAJIB PAJAK PADA NOMOR 8 KE INDUK BAGIAN C ANGKA 7 SPT WAJIB PAJAK
L76: PINDAHKAN JUMLAH PPh TERUTANG YANG DITANGGUNG OLEH SUAMI/ISTRI PADA NOMOR 9 KE INDUK BAGIAN C ANGKA 7 SPT SUAMI/ISTRI
D78: WAJIB PAJAK
Z81: NAMA DAN TTD
D83: NIK/NPWP | H83: X
D85: NAMA
D88: SUAMI/ISTRI
...

Sheet Lampiran 5
D5: PERHATIAN | V5: A. PENGHITUNGAN KOMPENSASI KERUGIAN FISKAL | AZ5: LAMPIRAN 5
D7: LAMPIRAN INI DIISI OLEH WAJIB PAJAK YANG | V7: B. PENGURANG PENGHASILAN NETO
D9: MENGAKUI KOMPENSASI KERUGIAN FISKAL | V9: C. PENGURANG PPh TERUTANG
D11: PENGURANG PENGHASILAN NETO, DAN/ATAU
D13: PENGURANG PPh TERUTANG | V13: NIK/NPWP | BA13: TAHUN PAJAK
C17: A. | D17: PENGHITUNGAN KOMPENSASI KERUGIAN FISKAL
C19: NO | J19: KOMPENSASI KERUGIAN FISKAL
D20: LABA/RUGI
D21: NETO FISKAL | K21: TAHUN | T21: TAHUN | AC21: TAHUN | AL21: TAHUN | AU21: TAHUN | BD21: TAHUN
D23: TAHUN PAJAK | G23: RUPIAH | J23: RUPIAH | S23: RUPIAH | AB23: RUPIAH | AK23: RUPIAH | AT23: RUPIAH (TAHUN PAJAK INI ) | BC23: RUPIAH (TAHUN PAJAK BERJALAN )
C26: (1) | D26: (2) | G26: (3) | J26: (4) | S26: (5) | AB26: (6) | AK26: (7) | AT26: (8) | BC26: (9)
C27: 1
C29: 2
C31: 3
C33: 4
C35: 5
C37: 6
C39: 7
C41: 8
C43: 9
C45: 10
C47: JUMLAH TABEL A
AI48: PINDAHKAN JUMLAH TABEL A KOLOM (8) KE LAMPIRAN INI BAGIAN B BARIS 6 KOLOM (4)
C50: B. | D50: PENGURANG PENGHASILAN NETO | AF50: C. | AG50: PENGURANG PPh TERUTANG
C52: NO | E52: KODE | K52: JENIS PENGURANG PENGHASILAN NETO | U52: JUMLAH PENGURANG PENGHASILAN NETO | AF52: NO | AH52: KODE | AR52: JENIS PENGURANG PPh TERUTANG | BC52: JUMLAH PENGURANG PPh TERUTANG
C55: (1) | E55: (2) | K55: (3) | U55: (4) | AF55: (1) | AH55: (2) | AR55: (3) | BC55: (4)
C56: 1 | AF56: 1
C58: 2 | AF58: 2
C60: 3 | AF60: 3
C62: 4 | AF62: 4
C64: 5 | E64: JUMLAH TABEL B | AF64: 5
C66: 6 | E66: JUMLAH KOMPENSASI KERUGIAN FISKAL | AF66: 6
C68: 7 | E68: JUMLAH PENGURANG PENGHASILAN NETO (B.5+B.6) | AF68: JUMLAH TABEL C
H70: PINDAHKAN JUMLAH PENGURANG PENGHASILAN NETO (B.7) DI BARIS 7 KOLOM (4) KE INDUK BAGIAN C ANGKA 3 | AW70: PINDAHKAN JUMLAH TABEL C KE INDUK BAGIAN C ANGKA 8
